Workbook
Name amznbeta: 'AMZN Equity Beta'!$H$2:$H$2
Name amznse: 'AMZN Equity Beta'!$H$3:$H$3
Name beta1b: '1b. Comps Analysis'!$B$25:$B$25
Name beta1c: '1c. Sector Based Comps Analysis'!$B$42:$B$42
Name MRP: 'MRP Historical'!$F$12
Name MRPSE: 'MRP Historical'!$F$15
Name RF: Assumptions!$B$12:$B$12
Name Scalar: Assumptions!$B$45
Name SMRP: '2. Calculating Cost of Equity'!$B$15:$B$15
Name SMRPH: '2. Calculating Cost of Equity'!$B$17:$B$17
Name SMRPL: '2. Calculating Cost of Equity'!$B$16:$B$16

Sheet Assumptions
A2: FIN 374
A3: CORPORATE VALUATIONS
A4: Dat Vuong
A7: ESTIMATING COST OF CAPITAL
A9: Assumption
A10: Tax Rate | B10: 0.21
A11: Cash Required (as a % of Revenue) | B11: 0.02
A12: Risk Free Rate (US 10 YT for SML) | B12: {=_FV(C12,"Price")/100} -> 0.042826 | C12: #VALUE!
A14: Assumed Debt Beta Mapping | D14: Capital Structure Assumption Choices
A15: IG | B15: 0.2 | D15: Stable, Investment Grade Debt
A16: NONIG | B16: 0.5 | D16: Stable DE Ratio
A17: UNK | B17: 0.3 | D17: *do for each comp and the target
A19: CREDIT RATING TRANSLATION
A20: S&P Rating | B20: IG or NONIG or UNK | C20: Debt Beta
A21: AAA | B21: IG | C21: =_xlfn.XLOOKUP(B21,$A$15:$A$17,$B$15:$B$17) -> 0.2
A22: AA+ | B22: IG | C22: =_xlfn.XLOOKUP(B22,$A$15:$A$17,$B$15:$B$17) -> 0.2
A23: AA | B23: IG | C23: =_xlfn.XLOOKUP(B23,$A$15:$A$17,$B$15:$B$17) -> 0.2
A24: AA- | B24: IG | C24: =_xlfn.XLOOKUP(B24,$A$15:$A$17,$B$15:$B$17) -> 0.2
A25: A+ | B25: IG | C25: =_xlfn.XLOOKUP(B25,$A$15:$A$17,$B$15:$B$17) -> 0.2
A26: A | B26: IG | C26: =_xlfn.XLOOKUP(B26,$A$15:$A$17,$B$15:$B$17) -> 0.2
A27: A- | B27: IG | C27: =_xlfn.XLOOKUP(B27,$A$15:$A$17,$B$15:$B$17) -> 0.2
A28: BBB+ | B28: IG | C28: =_xlfn.XLOOKUP(B28,$A$15:$A$17,$B$15:$B$17) -> 0.2
A29: BBB | B29: IG | C29: =_xlfn.XLOOKUP(B29,$A$15:$A$17,$B$15:$B$17) -> 0.2
A30: BBB- | B30: IG | C30: =_xlfn.XLOOKUP(B30,$A$15:$A$17,$B$15:$B$17) -> 0.2
A31: BB+ | B31: NONIG | C31: =_xlfn.XLOOKUP(B31,$A$15:$A$17,$B$15:$B$17) -> 0.5
A32: BB | B32: NONIG | C32: =_xlfn.XLOOKUP(B32,$A$15:$A$17,$B$15:$B$17) -> 0.5
... A43: UNK | B43: UNK | C43: =_xlfn.XLOOKUP(B43,$A$15:$A$17,$B$15:$B$17) -> 0.3
A45: Standard Error Scalar | B45: =0.5 -> 0.5

Sheet 1a. Historical Beta
A2: FIN 374
A3: CORPORATE VALUATIONS
A4: Dat Vuong
A7: Historical Equity Beta (AMZN)
A9: Equity Beta | B9: {=amznbeta} -> 1.4366578
A10: Standard Error of Beta | B10: {=amznse} -> 0.18577244
A11: Low Beta Estimate | B11: {=amznbeta-(amznse*Scalar)} -> 1.3437716
A12: High Beta Estimate | B12: {=amznbeta+(amznse*Scalar)} -> 1.5295441

Sheet Comps List
A2: FIN 374
A3: CORPORATE VALUATIONS
A4: Dat Vuong
A7: Company Comparable Analysis Data with Amazon (AMZN) as Target | E7: data from FactSet
A10: Identifier | B10: Name | C10: Fiscal Period | D10: Market Cap (MM) (USD) | E10: Total Debt (MM) (USD) | F10: Cash & Short Term Investments (MM) (USD) | G10: Revenue (MM) (USD) | H10: D/E Ratio | I10: Credit Rating | J10: Assumed Debt Beta
A11: 9988-HK | B11: Alibaba Group Holding Ltd. | C11: 45747 | D11: 304281 | E11: 34214.046 | F11: 63992.58 | G11: 138029.9 | H11: =E11/D11 -> 0.11244227 | I11: BB+ | J11: =_xlfn.XLOOKUP(I11,Assumptions!$A$21:$A$43,Assumptions!$C$21:$C$43) -> 0.5
A12: MELI-US | B12: MercadoLibre, Inc. | C12: 46022 | D12: 84664.3 | E12: 15163 | F12: 16166 | G12: 28893 | H12: =E12/D12 -> 0.17909556 | I12: BBB | J12: =_xlfn.XLOOKUP(I12,Assumptions!$A$21:$A$43,Assumptions!$C$21:$C$43) -> 0.2
A13: WMT-US | B13: Walmart, Inc. | C13: 46053 | D13: 1008390 | E13: 67095 | F13: 10727 | G13: 713163 | H13: =E13/D13 -> 0.066536757 | I13: BBB- | J13: =_xlfn.XLOOKUP(I13,Assumptions!$A$21:$A$43,Assumptions!$C$21:$C$43) -> 0.2
A14: COST-US | B14: Costco Wholesale Corp. | C14: 45900 | D14: 447393 | E14: 9935 | F14: 15284 | G14: 275235 | H14: =E14/D14 -> 0.022206427 | I14: B- | J14: =_xlfn.XLOOKUP(I14,Assumptions!$A$21:$A$43,Assumptions!$C$21:$C$43) -> 0.5
A15: MSFT-US | B15: Microsoft Corp. | C15: 45838 | D15: 2937210 | E15: 112184 | F15: 94565 | G15: 281724 | H15: =E15/D15 -> 0.038194069 | I15: BB | J15: =_xlfn.XLOOKUP(I15,Assumptions!$A$21:$A$43,Assumptions!$C$21:$C$43) -> 0.5
A16: ORCL-US | B16: Oracle Corp. | C16: 45808 | D16: 446104 | E16: 108952 | F16: 11203 | G16: 57399 | H16: =E16/D16 -> 0.24423005 | I16: UNK | J16: =_xlfn.XLOOKUP(I16,Assumptions!$A$21:$A$43,Assumptions!$C$21:$C$43) -> 0.3
A17: Average | E17: =AVERAGE(O11:O16,E26) -> 169934
A18: Median | E18: =MEDIAN(O11:O16,E26) -> 169934
A23: Target Company (AMZN)
A25: Identifier | B25: Name | C25: Fiscal Period | D25: Market Cap (MM) (USD) | E25: Total Debt (MM) (USD) | F25: Cash & Short Term Investments (MM) (USD) | G25: Revenue (MM) (USD) | H25: D/E Ratio | I25: Credit Rating | J25: Assumed Debt Beta
A26: AMZN-US | B26: Amazon.com, Inc. | C26: 46022 | D26: 2229320 | E26: 169934 | F26: 123329 | G26: 716924 | H26: =E26/D26 -> 0.076226832 | I26: A- | J26: =_xlfn.XLOOKUP(I26,Assumptions!$A$21:$A$43,Assumptions!$C$21:$C$43) -> 0.2

Sheet 1b. Comps Analysis
A2: FIN 374
A3: CORPORATE VALUATIONS
A4: Dat Vuong
A7: Comperable Companies for Firm Wide Analysis
A9: Unlevered Values
A11: Company Name | B11: Unlevered Beta | C11: SE of Beta | D11: D/E Ratio | E11: Assumed Debt Beta | F11: Equity Beta | G11: Required Cash | H11: Excess Cash | I11: Market Value Equity | J11: Cash Adjustment Factor | K11: Cash Adjusted Beta | L11: Adj. Beta Low | M11: Adj. Beta High
A12: Alibaba Group Holding Ltd. | B12: ='BABA Equity Beta'!H2 -> 0.085771244 | C12: ='BABA Equity Beta'!H3 -> 0.37903754 | D12: ='Comps List'!H11 -> 0.11244227 | E12: ='Comps List'!J11 -> 0.5 | F12: =(B12+(E12*D12))/(1+D12) -> 0.12764022 | G12: =Assumptions!$B$11*'Comps List'!G11 -> 2760.598 | H12: ='Comps List'!F11-'1b. Comps Analysis'!G12 -> 61231.982 | I12: ='Comps List'!D11 -> 304281 | J12: =IF(H12>0,I12/(I12-H12),1) -> 1.2519326 | K12: =F12*J12 -> 0.15979696 | L12: =K12-(C12*Assumptions!$B$45) -> -0.029721809 | M12: =K12+(C12*Assumptions!$B$45) -> 0.34931573
A13: MercadoLibre, Inc. | B13: ='MELI Equity Beta'!H2 -> 1.3673681 | C13: ='MELI Equity Beta'!H3 -> 0.3045188 | D13: ='Comps List'!H12 -> 0.17909556 | E13: ='Comps List'!J12 -> 0.2 | F13: =(B13+(E13*D13))/(1+D13) -> 1.1900539 | G13: =Assumptions!$B$11*'Comps List'!G12 -> 577.86 | H13: ='Comps List'!F12-'1b. Comps Analysis'!G13 -> 15588.14 | I13: ='Comps List'!D12 -> 84664.3 | J13: =IF(H13>0,I13/(I13-H13),1) -> 1.225666 | K13: =F13*J13 -> 1.4586086 | L13: =K13-(C13*Assumptions!$B$45) -> 1.3063492 | M13: =K13+(C13*Assumptions!$B$45) -> 1.610868
A14: Walmart, Inc. | B14: ='WMT Equity Beta'!H2 -> 1.0645001 | C14: ='WMT Equity Beta'!H3 -> 0.14129261 | D14: ='Comps List'!H13 -> 0.066536757 | E14: ='Comps List'!J13 -> 0.2 | F14: =(B14+(E14*D14))/(1+D14) -> 1.0105676 | G14: =Assumptions!$B$11*'Comps List'!G13 -> 14263.26 | H14: ='Comps List'!F13-'1b. Comps Analysis'!G14 -> -3536.26 | I14: ='Comps List'!D13 -> 1008390 | J14: =IF(H14>0,I14/(I14-H14),1) -> 1 | K14: =F14*J14 -> 1.0105676 | L14: =K14-(C14*Assumptions!$B$45) -> 0.93992129 | M14: =K14+(C14*Assumptions!$B$45) -> 1.0812139
A15: Costco Wholesale Corp. | B15: ='COST Equity Beta'!H2 -> 0.98168361 | C15: ='COST Equity Beta'!H3 -> 0.14111152 | D15: ='Comps List'!H14 -> 0.022206427 | E15: ='Comps List'!J14 -> 0.5 | F15: =(B15+(E15*D15))/(1+D15) -> 0.97121951 | G15: =Assumptions!$B$11*'Comps List'!G14 -> 5504.7 | H15: ='Comps List'!F14-'1b. Comps Analysis'!G15 -> 9779.3 | I15: ='Comps List'!D14 -> 447393 | J15: =IF(H15>0,I15/(I15-H15),1) -> 1.0223469 | K15: =F15*J15 -> 0.99292323 | L15: =K15-(C15*Assumptions!$B$45) -> 0.92236747 | M15: =K15+(C15*Assumptions!$B$45) -> 1.063479
A17: Target Company (AMZN)
A19: Company Name | B19: Unlevered Beta | C19: SE of Beta | D19: D/E Ratio | E19: Assumed Debt Beta | F19: Equity Beta | G19: Required Cash | H19: Excess Cash | I19: Market Value Equity | J19: Cash Adjustment Factor | K19: Cash Adjusted Beta | L19: Adj. Beta Low | M19: Adj. Beta High
A20: Amazon.com, Inc. | B20: ='AMZN Equity Beta'!H2 -> 1.4366578 | C20: ='AMZN Equity Beta'!H3 -> 0.18577244 | D20: ='Comps List'!H26 -> 0.076226832 | E20: ='Comps List'!J26 -> 0.2 | F20: =(B20+(E20*D20))/(1+D20) -> 1.349068 | G20: =Assumptions!$B$11*'Comps List'!G26 -> 14338.48 | H20: ='Comps List'!F26-'1b. Comps Analysis'!G20 -> 108990.52 | I20: ='Comps List'!D26 -> 2229320 | J20: =IF(H20>0,I20/(I20-H20),1) -> 1.0514026 | K20: =F20*J20 -> 1.4184137 | L20: =K20-(C20*Assumptions!$B$45) -> 1.3255275 | M20: =K20+(C20*Assumptions!$B$45) -> 1.5112999
A23: Average Comp. Asset Beta | B23: =AVERAGE(K12:K15) -> 0.90547409
A25: Relevered AMZN Beta | B25: =B23*(1+D20)-(E20*D20) -> 0.95925015
A27: Uncertainty Range
A29: Company Name | B29: Comp Implied AMZN Beta
A30: Alibaba Group Holding Ltd. | B30: =K12*(1+$D$20)-($E$20*$D$20) -> 0.15673241
A31: MercadoLibre, Inc. | B31: =K13*(1+$D$20)-($E$20*$D$20) -> 1.5545483
A32: Walmart, Inc. | B32: =K14*(1+$D$20)-($E$20*$D$20) -> 1.0723546
A33: Costco Wholesale Corp. | B33: =K15*(1+$D$20)-($E$20*$D$20) -> 1.0533653
A35: Standard Error | B35: =_xlfn.STDEV.S(B30:B33)/SQRT(COUNT(B30:B33)) -> 0.29155687
A37: AMZN Beta High | B37: =$B$25+$B$35*Assumptions!$B$45 -> 1.1050286
A38: AMZN Beta Low | B38: =$B$25-$B$35*Assumptions!$B$45 -> 0.81347171

Sheet 1c. Sector Based Comps Analysis
A2: FIN 374
A3: CORPORATE VALUATIONS
A4: Dat Vuong
A7: Unlevered Comperable Companies for Sector Analysis
A9: International Retail Segment
A10: Company Name | B10: Unlevered Beta | C10: SE of Beta | D10: D/E Ratio | E10: Assumed Debt Beta | F10: Equity Beta | G10: Required Cash | H10: Excess Cash | I10: Market Value Equity | J10: Cash Adjustment Factor | K10: Cash Adjusted Beta | L10: Adj. Beta Low | M10: Adj. Beta High
A11: Alibaba Group Holding Ltd. | B11: ='BABA Equity Beta'!H2 -> 0.085771244 | C11: ='BABA Equity Beta'!H3 -> 0.37903754 | D11: ='Comps List'!H11 -> 0.11244227 | E11: ='Comps List'!J11 -> 0.5 | F11: =(B11+(E11*D11))/(1+D11) -> 0.12764022 | G11: =Assumptions!$B$11*'Comps List'!G11 -> 2760.598 | H11: ='Comps List'!F11-'1c. Sector Based Comps Analysis'!G11 -> 61231.982 | I11: ='Comps List'!D11 -> 304281 | J11: =IF(H11>0,I11/(I11-H11),1) -> 1.2519326 | K11: =F11*J11 -> 0.15979696 | L11: =K11-(C11*Assumptions!$B$45) -> -0.029721809 | M11: =K11+(C11*Assumptions!$B$45) -> 0.34931573
A12: MercadoLibre, Inc. | B12: ='MELI Equity Beta'!H2 -> 1.3673681 | C12: ='MELI Equity Beta'!H3 -> 0.3045188 | D12: ='Comps List'!H12 -> 0.17909556 | E12: ='Comps List'!J12 -> 0.2 | F12: =(B12+(E12*D12))/(1+D12) -> 1.1900539 | G12: =Assumptions!$B$11*'Comps List'!G12 -> 577.86 | H12: ='Comps List'!F12-'1c. Sector Based Comps Analysis'!G12 -> 15588.14 | I12: ='Comps List'!D12 -> 84664.3 | J12: =IF(H12>0,I12/(I12-H12),1) -> 1.225666 | K12: =F12*J12 -> 1.4586086 | L12: =K12-(C12*Assumptions!$B$45) -> 1.3063492 | M12: =K12+(C12*Assumptions!$B$45) -> 1.610868
A13: Mean | K13: =AVERAGE(K11:K12) -> 0.80920277
A15: North America Retail Segment
A16: Company Name | B16: Unlevered Beta | C16: SE of Beta | D16: D/E Ratio | E16: Assumed Debt Beta | F16: Equity Beta | G16: Required Cash | H16: Excess Cash | I16: Market Value Equity | J16: Cash Adjustment Factor | K16: Cash Adjusted Beta | L16: Adj. Beta Low | M16: Adj. Beta High
A17: Walmart, Inc. | B17: ='WMT Equity Beta'!H2 -> 1.0645001 | C17: ='WMT Equity Beta'!H3 -> 0.14129261 | D17: ='Comps List'!H13 -> 0.066536757 | E17: ='Comps List'!J13 -> 0.2 | F17: =(B17+(E17*D17))/(1+D17) -> 1.0105676 | G17: =Assumptions!$B$11*'Comps List'!G13 -> 14263.26 | H17: ='Comps List'!F13-'1c. Sector Based Comps Analysis'!G17 -> -3536.26 | I17: ='Comps List'!D13 -> 1008390 | J17: =IF(H17>0,I17/(I17-H17),1) -> 1 | K17: =F17*J17 -> 1.0105676 | L17: =K17-(C17*Assumptions!$B$45) -> 0.93992129 | M17: =K17+(C17*Assumptions!$B$45) -> 1.0812139
A18: Costco Wholesale Corp. | B18: ='COST Equity Beta'!H2 -> 0.98168361 | C18: ='COST Equity Beta'!H3 -> 0.14111152 | D18: ='Comps List'!H14 -> 0.022206427 | E18: ='Comps List'!J14 -> 0.5 | F18: =(B18+(E18*D18))/(1+D18) -> 0.97121951 | G18: =Assumptions!$B$11*'Comps List'!G14 -> 5504.7 | H18: ='Comps List'!F14-'1c. Sector Based Comps Analysis'!G18 -> 9779.3 | I18: ='Comps List'!D14 -> 447393 | J18: =IF(H18>0,I18/(I18-H18),1) -> 1.0223469 | K18: =F18*J18 -> 0.99292323 | L18: =K18-(C18*Assumptions!$B$45) -> 0.92236747 | M18: =K18+(C18*Assumptions!$B$45) -> 1.063479
A19: Mean | K19: =AVERAGE(K17:K18) -> 1.0017454
A21: AWS Segment
A22: Company Name | B22: Unlevered Beta | C22: SE of Beta | D22: D/E Ratio | E22: Assumed Debt Beta | F22: Equity Beta | G22: Required Cash | H22: Excess Cash | I22: Market Value Equity | J22: Cash Adjustment Factor | K22: Cash Adjusted Beta | L22: Adj. Beta Low | M22: Adj. Beta High
A23: Microsoft Corp. | B23: ='MSFT Equity Beta'!H2 -> 1.0757582 | C23: ='MSFT Equity Beta'!H3 -> 0.13447305 | D23: ='Comps List'!H15 -> 0.038194069 | E23: ='Comps List'!J15 -> 0.5 | F23: =(B23+(E23*D23))/(1+D23) -> 1.0545767 | G23: =Assumptions!$B$11*'Comps List'!G15 -> 5634.48 | H23: ='Comps List'!F15-'1c. Sector Based Comps Analysis'!G23 -> 88930.52 | I23: ='Comps List'!D15 -> 2937210 | J23: =IF(H23>0,I23/(I23-H23),1) -> 1.0312225 | K23: =F23*J23 -> 1.0875033 | L23: =K23-(C23*Assumptions!$B$45) -> 1.0202667 | M23: =K23+(C23*Assumptions!$B$45) -> 1.1547398
A24: Oracle Corp. | B24: ='ORCL Equity Beta'!H2 -> 1.4690356 | C24: ='ORCL Equity Beta'!H3 -> 0.25078233 | D24: ='Comps List'!H16 -> 0.24423005 | E24: ='Comps List'!J16 -> 0.3 | F24: =(B24+(E24*D24))/(1+D24) -> 1.2395655 | G24: =Assumptions!$B$11*'Comps List'!G16 -> 1147.98 | H24: ='Comps List'!F16-'1c. Sector Based Comps Analysis'!G24 -> 10055.02 | I24: ='Comps List'!D16 -> 446104 | J24: =IF(H24>0,I24/(I24-H24),1) -> 1.0230594 | K24: =F24*J24 -> 1.2681491 | L24: =K24-(C24*Assumptions!$B$45) -> 1.1427579 | M24: =K24+(C24*Assumptions!$B$45) -> 1.3935403
A25: Mean | K25: =AVERAGE(K23:K24) -> 1.1778262
A27: Target Company (AMZN)
A29: Company Name | B29: Unlevered Beta | C29: SE of Beta | D29: D/E Ratio | E29: Assumed Debt Beta | F29: Equity Beta | G29: Required Cash | H29: Excess Cash | I29: Market Value Equity | J29: Cash Adjustment Factor | K29: Cash Adjusted Beta | L29: Adj. Beta Low | M29: Adj. Beta High
A30: Amazon.com, Inc. | B30: ='AMZN Equity Beta'!H2 -> 1.4366578 | C30: ='AMZN Equity Beta'!H3 -> 0.18577244 | D30: ='Comps List'!H26 -> 0.076226832 | E30: ='Comps List'!J26 -> 0.2 | F30: =(B30+(E30*D30))/(1+D30) -> 1.349068 | G30: =Assumptions!$B$11*'Comps List'!G26 -> 14338.48 | H30: ='Comps List'!F26-'1c. Sector Based Comps Analysis'!G30 -> 108990.52 | I30: ='Comps List'!D26 -> 2229320 | J30: =IF(H30>0,I30/(I30-H30),1) -> 1.0514026 | K30: =F30*J30 -> 1.4184137 | L30: =K30-(C30*Assumptions!$B$45) -> 1.3255275 | M30: =K30+(C30*Assumptions!$B$45) -> 1.5112999
A32: Segment Weights (As a Proportion of Net Sales From 10K)
A34: Net Sales: | B34: Value | C34: Percent of Net | D34: Weighted AVG Beta | E34: Segment Standard Error
A35: North America | B35: 426305 | C35: =B35/$B$38 -> 0.59463067 | D35: =C35*K13 -> 0.48117679 | E35: =_xlfn.STDEV.S(K11:K12)/SQRT(COUNT(K11:K12)) -> 0.64940581
A36: International | B36: 161894 | C36: =B36/$B$38 -> 0.22581752 | D36: =C36*K19 -> 0.22621167 | E36: =_xlfn.STDEV.S(K17:K18)/SQRT(COUNT(K17:K18)) -> 0.0088221794
A37: AWS | B37: 128725 | C37: =B37/$B$38 -> 0.17955181 | D37: =C37*K25 -> 0.21148082 | E37: =_xlfn.STDEV.S(K23:K24)/SQRT(COUNT(K23:K24)) -> 0.090322919
A38: Consolidated | B38: =SUM(B35:B37) -> 716924
A40: Weighted Unlevered Beta | B40: =SUM(D35:D37) -> 0.91886927
A42: Relevered AMZN Beta | B42: =B40*(1+D30)-(E30*D30) -> 0.9736664
A44: Combined Standard Error | B44: =SQRT((C35^2*E35^2)+(C36^2*E36^2)+(C37^2*E37^2)) -> 0.38650215
A46: AMZN Beta High | B46: =B42-(Assumptions!B45*B44) -> 0.78041532
A47: AMZN Beta Low | B47: =B42+(Assumptions!B45*B44) -> 1.1669175

Sheet 2. Calculating Cost of Equity
A2: FIN 374
A3: CORPORATE VALUATIONS
A4: Dat Vuong
A7: Part A: Historical Market Risk Premium
A9: Expected Market Risk Premium | B9: =MRP -> 0.088628283
A10: Estimate Low | B10: =MRP-MRPSE*Scalar -> 0.078514746
A11: Estimate High | B11: =MRP+MRPSE*Scalar -> 0.09874182
A13: Part B: Scenario Based MRP
A15: Expected Market Risk Premium | B15: ='MRP Scenario Analysis'!C14 -> 0.0775
A16: Estimate Low | B16: ='MRP Scenario Analysis'!C14-'MRP Scenario Analysis'!F14*Scalar -> 0.06460351
A17: Esimtate High | B17: ='MRP Scenario Analysis'!C14+'MRP Scenario Analysis'!F14*Scalar -> 0.09039649
A19: Historical MRP and Historical Beta
A21: Beta | B21: {=amznbeta} -> 1.4366578
A22: Market Risk Premium | B22: =$B$9 -> 0.088628283
A23: Risk Free Rate | B23: {=RF} -> 0.042826
A24: Cost of Equity | B24: =B23+(B22*B21) -> 0.17015452
A25: Cost of Equity Low | B25: =B23+($B$10*B21) -> 0.15562483
A26: Cost of Equity High | B26: =B23+($B$11*B21) -> 0.18468421
A28: Historical MRP and Pure Play Comperables Analysis
A30: Beta | B30: {=beta1b} -> 0.95925015
A31: Market Risk Premium | B31: =$B$9 -> 0.088628283
A32: Risk Free Rate | B32: {=RF} -> 0.042826
A33: Cost of Equity | B33: =B32+(B31*B30) -> 0.12784269
A34: Cost of Equity Low | B34: =B32+($B$10*B30) -> 0.11814128
A35: Cost of Equity High | B35: =B32+($B$11*B30) -> 0.13754411
A37: Historical MRP and Sector Weighted Comperables Analysis
A39: Beta | B39: {=beta1c} -> 0.9736664
A40: Market Risk Premium | B40: =$B$9 -> 0.088628283
A41: Risk Free Rate | B41: {=RF} -> 0.042826
A42: Cost of Equity | B42: =B41+(B40*B39) -> 0.12912038
A43: Cost of Equity Low | B43: =B41+($B$10*B39) -> 0.11927317
A44: Cost of Equity High | B44: =B41+($B$11*B39) -> 0.13896759
A46: Scenario Based MRP and Historical Beta
A48: Beta | B48: {=amznbeta} -> 1.4366578
A49: Market Risk Premium | B49: {=SMRP} -> 0.0775
A50: Risk Free Rate | B50: {=RF} -> 0.042826
A51: Cost of Equity | B51: =B50+(B49*B48) -> 0.15416698
A52: Cost of Equity Low | B52: {=B50+(SMRPL*B48)} -> 0.13563914
A53: Cost of Equity High | B53: {=B50+(SMRPH*B48)} -> 0.17269483
A55: Scenario Based MRP Pure Play Comperables Analysis
...

Sheet US Rev Multiplies
B2: Industry Name | C2: Number of firms | D2: Price/Sales | E2: Net Margin | F2: EV/Sales | G2: Pre-tax Operating Margin
B3: Advertising | C3: 52 | D3: 1.64 | E3: -0.003 | F3: 2.12 | G3: 0.1005
B4: Aerospace/Defense | C4: 79 | D4: 3.17 | E4: 0.0499 | F4: 3.57 | G4: 0.087
B5: Air Transport | C5: 23 | D5: 0.58 | E5: 0.0251 | F5: 1.03 | G5: 0.0488
B6: Apparel | C6: 35 | D6: 1.27 | E6: 0.0385 | F6: 1.59 | G6: 0.0989
B7: Auto & Truck | C7: 33 | D7: 3.34 | E7: 0.0129 | F7: 3.88 | G7: 0.0238
B8: Auto Parts | C8: 35 | D8: 0.64 | E8: 0.0072 | F8: 0.82 | G8: 0.058
B9: Bank (Money Center) | C9: 15 | D9: 4.09 | E9: 0.2889 | F9: 8.31 | G9: 0.0008
B10: Banks (Regional) | C10: 568 | D10: 3.67 | E10: 0.2749 | F10: 4.28 | G10: -0.0012
B11: Beverage (Alcoholic) | C11: 14 | D11: 1.75 | E11: 0.0056 | F11: 2.45 | G11: 0.2279
B12: Beverage (Soft) | C12: 27 | D12: 3.57 | E12: 0.134 | F12: 4.16 | G12: 0.2063
B13: Broadcasting | C13: 24 | D13: 0.83 | E13: 0.0206 | F13: 1.4 | G13: 0.1235
B14: Brokerage & Investment Banking | C14: 32 | D14: 2.87 | E14: 0.1445 | F14: 5.78 | G14: -0.0012
... B98: Total Market (without financials) | C98: 4822 | D98: 3.03 | E98: 0.0856 | F98: 3.46 | G98: 0.1306
B100: Source: https://pages.stern.nyu.edu/~adamodar/New_Home_Page/datafile/psdata.html

Sheet Global Rev Multiplies
B2: Industry Name | C2: Number of firms | D2: Price/Sales | E2: Net Margin | F2: EV/Sales | G2: Pre-tax Operating Margin
B3: Advertising | C3: 417 | D3: 1.43 | E3: 0.0307 | F3: 1.65 | G3: 0.0803
B4: Aerospace/Defense | C4: 300 | D4: 2.2 | E4: 0.0515 | F4: 2.47 | G4: 0.0802
B5: Air Transport | C5: 151 | D5: 0.76 | E5: 0.0549 | F5: 1.31 | G5: 0.0779
B6: Apparel | C6: 1194 | D6: 2.04 | E6: 0.0745 | F6: 2.3 | G6: 0.1433
B7: Auto & Truck | C7: 162 | D7: 1.02 | E7: 0.0543 | F7: 1.37 | G7: 0.0672
B8: Auto Parts | C8: 780 | D8: 0.63 | E8: 0.0308 | F8: 0.74 | G8: 0.0529
B9: Bank (Money Center) | C9: 621 | D9: NA | E9: NA | F9: NA | G9: NA
B10: Banks (Regional) | C10: 849 | D10: NA | E10: NA | F10: NA | G10: NA
B11: Beverage (Alcoholic) | C11: 216 | D11: 2.53 | E11: 0.1151 | F11: 2.94 | G11: 0.2249
B12: Beverage (Soft) | C12: 101 | D12: 2.97 | E12: 0.1209 | F12: 3.37 | G12: 0.1735
B13: Broadcasting | C13: 126 | D13: 0.74 | E13: -0.0144 | F13: 1.2 | G13: 0.1001
B14: Brokerage & Investment Banking | C14: 606 | D14: NA | E14: NA | F14: NA | G14: NA
B15: Building Materials | C15: 462 | D15: 1.56 | E15: 0.0689 | F15: 1.79 | G15: 0.1064
B16: Business & Consumer Services | C16: 974 | D16: 2 | E16: 0.061 | F16: 2.23 | G16: 0.0986
B17: Cable TV | C17: 45 | D17: 1.1 | E17: 0.0633 | F17: 2.3 | G17: 0.1689
B18: Chemical (Basic) | C18: 897 | D18: 0.86 | E18: 0.0185 | F18: 1.2 | G18: 0.0439
B19: Chemical (Diversified) | C19: 64 | D19: 0.67 | E19: 0.0104 | F19: 1.01 | G19: 0.0545
B20: Chemical (Specialty) | C20: 951 | D20: 1.91 | E20: 0.0597 | F20: 2.22 | G20: 0.1063
B21: Coal & Related Energy | C21: 216 | D21: 1.61 | E21: 0.1383 | F21: 1.61 | G21: 0.2075
B22: Computer Services | C22: 1182 | D22: 1.4 | E22: 0.0452 | F22: 1.51 | G22: 0.0728
B23: Computers/Peripherals | C23: 342 | D23: 3.26 | E23: 0.1007 | F23: 3.35 | G23: 0.1308
B24: Construction Supplies | C24: 804 | D24: 1.16 | E24: 0.0615 | F24: 1.44 | G24: 0.0947
B25: Diversified | C25: 335 | D25: 1.4 | E25: 0.1315 | F25: 1.96 | G25: 0.1915
B26: Drugs (Biotechnology) | C26: 1223 | D26: 6.2 | E26: -0.095 | F26: 6.74 | G26: 0.0008
... B35: Farming/Agriculture | C35: 429 | D35: 0.72 | E35: 0.0487 | F35: 1.1 | G35: 0.0685
B36: Financial Svcs. (Non-bank & Insurance) | C36: 1117 | D36: NA | E36: NA | F36: NA | G36: NA
B37: Food Processing | C37: 1424 | D37: 1.02 | E37: 0.051 | F37: 1.3 | G37: 0.0847
B38: Food Wholesalers | C38: 188 | D38: 0.28 | E38: 0.0141 | F38: 0.42 | G38: 0.0258
B39: Furn/Home Furnishings | C39: 380 | D39: 1.04 | E39: 0.0579 | F39: 1.08 | G39: 0.0742
B40: Green & Renewable Energy | C40: 260 | D40: 4.2 | E40: 0.141 | F40: 6.99 | G40: 0.3022
B41: Healthcare Products | C41: 850 | D41: 4.01 | E41: 0.0847 | F41: 4.39 | G41: 0.1393
B42: Healthcare Support Services | C42: 480 | D42: 0.43 | E42: 0.0157 | F42: 0.55 | G42: 0.0346
B43: Heathcare Information and Technology | C43: 435 | D43: 4.66 | E43: 0.0531 | F43: 5.12 | G43: 0.1284
B44: Homebuilding | C44: 165 | D44: 0.95 | E44: 0.0928 | F44: 1.15 | G44: 0.1199
B45: Hospitals/Healthcare Facilities | C45: 245 | D45: 1.38 | E45: 0.076 | F45: 1.99 | G45: 0.1106
B46: Hotel/Gaming | C46: 660 | D46: 2.54 | E46: 0.0748 | F46: 3.38 | G46: 0.1403
B47: Household Products | C47: 554 | D47: 2.76 | E47: 0.0954 | F47: 3.03 | G47: 0.1609
B48: Information Services | C48: 85 | D48: 1.53 | E48: 0.0579 | F48: 1.95 | G48: 0.114
... B98: Total Market (without financials) | C98: 42750 | D98: 1.56 | E98: 0.0577 | F98: 1.9 | G98: 0.0977
...

Sheet MRP Historical
B2: SML Equation
B4: ki = E(ri) + beta(E(MRP)) | E4: MRP = E(rm - rf)
B6: What to find Beta which is stage 1, stage 2 is to get that data into CAPM
B8: Estimating the MRP (Market Risk Premium, using Historical Data)
B10: Annual Factors: January-December
C11: Mkt-RF | D11: RF | F11: E(MRP) = E(Mkr-rf)
B12: 1927 | C12: 0.2944 | D12: 0.0312 | F12: =AVERAGE(C12:C110) -> 0.088628283
B13: 1928 | C13: 0.3556 | D13: 0.0356
B14: 1929 | C14: -0.1958 | D14: 0.0475 | F14: Standard Error MRP
B15: 1930 | C15: -0.3114 | D15: 0.0241 | F15: =STDEV(C12:C110)/SQRT(COUNT(C12:C110)) -> 0.020227074
B16: 1931 | C16: -0.4484 | D16: 0.0107
B17: 1932 | C17: -0.096 | D17: 0.0096
B18: 1933 | C18: 0.5649 | D18: 0.003
B19: 1934 | C19: 0.0309 | D19: 0.0016
B20: 1935 | C20: 0.4487 | D20: 0.0017
B21: 1936 | C21: 0.3198 | D21: 0.0018
B22: 1937 | C22: -0.3501 | D22: 0.0031
B23: 1938 | C23: 0.2822 | D23: -0.0002
B24: 1939 | C24: 0.025 | D24: 0.0002
B25: 1940 | C25: -0.072 | D25: 0
B26: 1941 | C26: -0.1058 | D26: 0.0006
B27: 1942 | C27: 0.1621 | D27: 0.0027
... B110: 2025 | C110: 0.133 | D110: 0.0425

Sheet MRP Scenario Analysis
B2: Estimating the MRP using Given Scenario Analysis
B4: Assumed Scenario Analysis
B6: Market Scenario
B8: Market Scenario | C8: Probability of Scenario | D8: MRP in Scenario | E8: Expected MRP | F8: p(s) * (rs - Er)^2
B9: Aggressive | C9: 0.5 | D9: 0.1 | E9: =AVERAGE($D$9:$D$11) -> 0.068333333 | F9: =C9*(D9-$E$9)^2 -> 0.00050138889
B10: Moderate | C10: 0.3 | D10: 0.065 | E10: =AVERAGE($D$9:$D$11) -> 0.068333333 | F10: =C10*(D10-$E$9)^2 -> 3.3333333e-06
B11: Conservative | C11: 0.2 | D11: 0.04 | E11: =AVERAGE($D$9:$D$11) -> 0.068333333 | F11: =C11*(D11-$E$9)^2 -> 0.00016055556
C12: =SUM(C9:C11) -> 1 | F12: =SUM(F9:F11) -> 0.00066527778 | G12: <- Variance
B14: Expected MRP | C14: =SUMPRODUCT(C9:C11,D9:D11) -> 0.0775 | F14: =SQRT(F12) -> 0.025792979 | G14: <- SD
B15: Standard Deviation | C15: =F14 -> 0.025792979
B17: Use CAPM for our 3 Betas

Sheet TEGNA Equity Beta
B2: #VALUE! | G2: Beta | H2: =INDEX(LINEST(K11:K70,L11:L70,1,1),1,1) -> 0.21866218
B3: #VALUE! | G3: SE Beta | H3: =INDEX(LINEST(K11:K70,L11:L70,1,1),2,1) -> 0.21258935
B4: #VALUE!
B6: 44256
B7: 46082
C9: Price TEGNA | D9: Price S&P 500 | E9: Price US10Y
B10: {=_xlfn.STOCKHISTORY(B2,$B$6,$B$7,2,0)} -> 44256 | C10: 18.83 | D10: {=_xlfn.STOCKHISTORY(B3,$B$6,$B$7,2,0,1)} -> 396.33 | E10: {=_xlfn.STOCKHISTORY(B4,$B$6,$B$7,2,0,1)} -> 94.4844 | G10: ri | H10: rm | I10: rf | K10: ri-rf | L10: rm-rf
B11: 44287 | C11: 20.06 | D11: 417.3 | E11: 95.4844 | G11: =(C11-C10)/C10 -> 0.065321296 | H11: =(D11-D10)/D10 -> 0.052910453 | I11: =(E11-E10)/E10 -> 0.010583758 | K11: =G11-I11 -> 0.054737538 | L11: =H11-I11 -> 0.042326696
B12: 44317 | C12: 19.39 | D12: 420.04 | E12: 100.1406 | G12: =(C12-C11)/C11 -> -0.033399801 | H12: =(D12-D11)/D11 -> 0.0065660197 | I12: =(E12-E11)/E11 -> 0.048763987 | K12: =G12-I12 -> -0.082163787 | L12: =H12-I12 -> -0.042197967
B13: 44348 | C13: 18.76 | D13: 428.06 | E13: 101.4063 | G13: =(C13-C12)/C12 -> -0.032490975 | H13: =(D13-D12)/D12 -> 0.01909342 | I13: =(E13-E12)/E12 -> 0.012639229 | K13: =G13-I13 -> -0.045130204 | L13: =H13-I13 -> 0.0064541904
B14: 44378 | C14: 17.72 | D14: 438.51 | E14: 103.6719 | G14: =(C14-C13)/C13 -> -0.0554371 | H14: =(D14-D13)/D13 -> 0.024412466 | I14: =(E14-E13)/E13 -> 0.022341807 | K14: =G14-I14 -> -0.077778907 | L14: =H14-I14 -> 0.0020706584
B15: 44409 | C15: 17.72 | D15: 451.56 | E15: 99.4063 | G15: =(C15-C14)/C14 -> 0 | H15: =(D15-D14)/D14 -> 0.029759869 | I15: =(E15-E14)/E14 -> -0.04114519 | K15: =G15-I15 -> 0.04114519 | L15: =H15-I15 -> 0.070905058
B16: 44440 | C16: 19.72 | D16: 429.14 | E16: 97.7031 | G16: =(C16-C15)/C15 -> 0.11286682 | H16: =(D16-D15)/D15 -> -0.049650102 | I16: =(E16-E15)/E15 -> -0.017133723 | K16: =G16-I16 -> 0.13000054 | L16: =H16-I16 -> -0.032516379
B17: 44470 | C17: 19.66 | D17: 459.25 | E17: 97.0781 | G17: =(C17-C16)/C16 -> -0.0030425963 | H17: =(D17-D16)/D16 -> 0.070163583 | I17: =(E17-E16)/E16 -> -0.0063969311 | K17: =G17-I17 -> 0.0033543348 | L17: =H17-I17 -> 0.076560514
B18: 44501 | C18: 19.75 | D18: 455.56 | E18: 98.6563 | G18: =(C18-C17)/C17 -> 0.004577823 | H18: =(D18-D17)/D17 -> -0.0080348394 | I18: =(E18-E17)/E17 -> 0.016257014 | K18: =G18-I18 -> -0.011679191 | L18: =H18-I18 -> -0.024291853
B19: 44531 | C19: 18.56 | D19: 474.96 | E19: 98.75 | G19: =(C19-C18)/C18 -> -0.060253165 | H19: =(D19-D18)/D18 -> 0.04258495 | I19: =(E19-E18)/E18 -> 0.00094976195 | K19: =G19-I19 -> -0.061202927 | L19: =H19-I19 -> 0.041635188
B20: 44562 | C20: 19.36 | D20: 449.91 | E20: 96.2969 | G20: =(C20-C19)/C19 -> 0.043103448 | H20: =(D20-D19)/D19 -> -0.052741283 | I20: =(E20-E19)/E19 -> -0.024841519 | K20: =G20-I20 -> 0.067944967 | L20: =H20-I20 -> -0.027899764
B21: 44593 | C21: 22.92 | D21: 436.63 | E21: 99.75 | G21: =(C21-C20)/C20 -> 0.1838843 | H21: =(D21-D20)/D20 -> -0.029517015 | I21: =(E21-E20)/E20 -> 0.035858891 | K21: =G21-I21 -> 0.14802541 | L21: =H21-I21 -> -0.065375905
B22: 44621 | C22: 22.4 | D22: 451.64 | E22: 95.8125 | G22: =(C22-C21)/C21 -> -0.022687609 | H22: =(D22-D21)/D21 -> 0.034376932 | I22: =(E22-E21)/E21 -> -0.039473684 | K22: =G22-I22 -> 0.016786075 | L22: =H22-I22 -> 0.073850617
... B70: 46082 | C70: 20.3 | D70: 662.29 | E70: 98.7344 | G70: =(C70-C69)/C69 -> -0.031026253 | H70: =(D70-D69)/D69 -> -0.034548609 | I70: =(E70-E69)/E69 -> -0.026647936 | K70: =G70-I70 -> -0.0043783171 | L70: =H70-I70 -> -0.0079006727

Sheet AMZN Equity Beta
B2: #VALUE! | G2: Beta | H2: =INDEX(LINEST(K11:K70,L11:L70,1,1),1,1) -> 1.4366578
B3: #VALUE! | G3: SE Beta | H3: =INDEX(LINEST(K11:K70,L11:L70,1,1),2,1) -> 0.18577244
B4: #VALUE!
B6: 44256
B7: 46082
C9: Price TEGNA | D9: Price S&P 500 | E9: Price US10Y
B10: {=_xlfn.STOCKHISTORY(B2,$B$6,$B$7,2,0)} -> 44256 | C10: 154.704 | D10: {=_xlfn.STOCKHISTORY(B3,$B$6,$B$7,2,0,1)} -> 396.33 | E10: {=_xlfn.STOCKHISTORY(B4,$B$6,$B$7,2,0,1)} -> 94.4844 | G10: ri | H10: rm | I10: rf | K10: ri-rf | L10: rm-rf
B11: 44287 | C11: 173.371 | D11: 417.3 | E11: 95.4844 | G11: =(C11-C10)/C10 -> 0.12066268 | H11: =(D11-D10)/D10 -> 0.052910453 | I11: =(E11-E10)/E10 -> 0.010583758 | K11: =G11-I11 -> 0.11007893 | L11: =H11-I11 -> 0.042326696
B12: 44317 | C12: 161.1535 | D12: 420.04 | E12: 100.1406 | G12: =(C12-C11)/C11 -> -0.070470263 | H12: =(D12-D11)/D11 -> 0.0065660197 | I12: =(E12-E11)/E11 -> 0.048763987 | K12: =G12-I12 -> -0.11923425 | L12: =H12-I12 -> -0.042197967
B13: 44348 | C13: 172.008 | D13: 428.06 | E13: 101.4063 | G13: =(C13-C12)/C12 -> 0.067355037 | H13: =(D13-D12)/D12 -> 0.01909342 | I13: =(E13-E12)/E12 -> 0.012639229 | K13: =G13-I13 -> 0.054715808 | L13: =H13-I13 -> 0.0064541904
B14: 44378 | C14: 166.3795 | D14: 438.51 | E14: 103.6719 | G14: =(C14-C13)/C13 -> -0.032722315 | H14: =(D14-D13)/D13 -> 0.024412466 | I14: =(E14-E13)/E13 -> 0.022341807 | K14: =G14-I14 -> -0.055064122 | L14: =H14-I14 -> 0.0020706584
B15: 44409 | C15: 173.5395 | D15: 451.56 | E15: 99.4063 | G15: =(C15-C14)/C14 -> 0.043034148 | H15: =(D15-D14)/D14 -> 0.029759869 | I15: =(E15-E14)/E14 -> -0.04114519 | K15: =G15-I15 -> 0.084179338 | L15: =H15-I15 -> 0.070905058
B16: 44440 | C16: 164.252 | D16: 429.14 | E16: 97.7031 | G16: =(C16-C15)/C15 -> -0.053518075 | H16: =(D16-D15)/D15 -> -0.049650102 | I16: =(E16-E15)/E15 -> -0.017133723 | K16: =G16-I16 -> -0.036384352 | L16: =H16-I16 -> -0.032516379
B17: 44470 | C17: 168.6215 | D17: 459.25 | E17: 97.0781 | G17: =(C17-C16)/C16 -> 0.026602416 | H17: =(D17-D16)/D16 -> 0.070163583 | I17: =(E17-E16)/E16 -> -0.0063969311 | K17: =G17-I17 -> 0.032999347 | L17: =H17-I17 -> 0.076560514
B18: 44501 | C18: 175.3535 | D18: 455.56 | E18: 98.6563 | G18: =(C18-C17)/C17 -> 0.039923735 | H18: =(D18-D17)/D17 -> -0.0080348394 | I18: =(E18-E17)/E17 -> 0.016257014 | K18: =G18-I18 -> 0.023666721 | L18: =H18-I18 -> -0.024291853
B19: 44531 | C19: 166.717 | D19: 474.96 | E19: 98.75 | G19: =(C19-C18)/C18 -> -0.04925194 | H19: =(D19-D18)/D18 -> 0.04258495 | I19: =(E19-E18)/E18 -> 0.00094976195 | K19: =G19-I19 -> -0.050201702 | L19: =H19-I19 -> 0.041635188
B20: 44562 | C20: 149.5735 | D20: 449.91 | E20: 96.2969 | G20: =(C20-C19)/C19 -> -0.10282995 | H20: =(D20-D19)/D19 -> -0.052741283 | I20: =(E20-E19)/E19 -> -0.024841519 | K20: =G20-I20 -> -0.077988426 | L20: =H20-I20 -> -0.027899764
B21: 44593 | C21: 153.563 | D21: 436.63 | E21: 99.75 | G21: =(C21-C20)/C20 -> 0.026672505 | H21: =(D21-D20)/D20 -> -0.029517015 | I21: =(E21-E20)/E20 -> 0.035858891 | K21: =G21-I21 -> -0.0091863851 | L21: =H21-I21 -> -0.065375905
B22: 44621 | C22: 162.9975 | D22: 451.64 | E22: 95.8125 | G22: =(C22-C21)/C21 -> 0.061437325 | H22: =(D22-D21)/D21 -> 0.034376932 | I22: =(E22-E21)/E21 -> -0.039473684 | K22: =G22-I22 -> 0.10091101 | L22: =H22-I22 -> 0.073850617
... B70: 46082 | C70: 207.67 | D70: 662.29 | E70: 98.7344 | G70: =(C70-C69)/C69 -> -0.011095238 | H70: =(D70-D69)/D69 -> -0.034548609 | I70: =(E70-E69)/E69 -> -0.026647936 | K70: =G70-I70 -> 0.015552698 | L70: =H70-I70 -> -0.0079006727

Sheet COST Equity Beta
B2: #VALUE! | G2: Beta | H2: =INDEX(LINEST(K11:K70,L11:L70,1,1),1,1) -> 0.98168361
B3: #VALUE! | G3: SE Beta | H3: =INDEX(LINEST(K11:K70,L11:L70,1,1),2,1) -> 0.14111152
B4: #VALUE!
B6: 44256
B7: 46082
C9: Price TEGNA | D9: Price S&P 500 | E9: Price US10Y
B10: {=_xlfn.STOCKHISTORY(B2,$B$6,$B$7,2,0)} -> 44256 | C10: 352.48 | D10: {=_xlfn.STOCKHISTORY(B3,$B$6,$B$7,2,0,1)} -> 396.33 | E10: {=_xlfn.STOCKHISTORY(B4,$B$6,$B$7,2,0,1)} -> 94.4844 | G10: ri | H10: rm | I10: rf | K10: ri-rf | L10: rm-rf
B11: 44287 | C11: 372.09 | D11: 417.3 | E11: 95.4844 | G11: =(C11-C10)/C10 -> 0.055634362 | H11: =(D11-D10)/D10 -> 0.052910453 | I11: =(E11-E10)/E10 -> 0.010583758 | K11: =G11-I11 -> 0.045050604 | L11: =H11-I11 -> 0.042326696
B12: 44317 | C12: 378.27 | D12: 420.04 | E12: 100.1406 | G12: =(C12-C11)/C11 -> 0.016608885 | H12: =(D12-D11)/D11 -> 0.0065660197 | I12: =(E12-E11)/E11 -> 0.048763987 | K12: =G12-I12 -> -0.032155102 | L12: =H12-I12 -> -0.042197967
B13: 44348 | C13: 395.67 | D13: 428.06 | E13: 101.4063 | G13: =(C13-C12)/C12 -> 0.04599889 | H13: =(D13-D12)/D12 -> 0.01909342 | I13: =(E13-E12)/E12 -> 0.012639229 | K13: =G13-I13 -> 0.03335966 | L13: =H13-I13 -> 0.0064541904
B14: 44378 | C14: 429.72 | D14: 438.51 | E14: 103.6719 | G14: =(C14-C13)/C13 -> 0.086056562 | H14: =(D14-D13)/D13 -> 0.024412466 | I14: =(E14-E13)/E13 -> 0.022341807 | K14: =G14-I14 -> 0.063714755 | L14: =H14-I14 -> 0.0020706584
B15: 44409 | C15: 455.49 | D15: 451.56 | E15: 99.4063 | G15: =(C15-C14)/C14 -> 0.059969282 | H15: =(D15-D14)/D14 -> 0.029759869 | I15: =(E15-E14)/E14 -> -0.04114519 | K15: =G15-I15 -> 0.10111447 | L15: =H15-I15 -> 0.070905058
B16: 44440 | C16: 449.35 | D16: 429.14 | E16: 97.7031 | G16: =(C16-C15)/C15 -> -0.013479989 | H16: =(D16-D15)/D15 -> -0.049650102 | I16: =(E16-E15)/E15 -> -0.017133723 | K16: =G16-I16 -> 0.0036537343 | L16: =H16-I16 -> -0.032516379
B17: 44470 | C17: 491.54 | D17: 459.25 | E17: 97.0781 | G17: =(C17-C16)/C16 -> 0.093891176 | H17: =(D17-D16)/D16 -> 0.070163583 | I17: =(E17-E16)/E16 -> -0.0063969311 | K17: =G17-I17 -> 0.10028811 | L17: =H17-I17 -> 0.076560514
B18: 44501 | C18: 539.38 | D18: 455.56 | E18: 98.6563 | G18: =(C18-C17)/C17 -> 0.097326769 | H18: =(D18-D17)/D17 -> -0.0080348394 | I18: =(E18-E17)/E17 -> 0.016257014 | K18: =G18-I18 -> 0.081069755 | L18: =H18-I18 -> -0.024291853
B19: 44531 | C19: 567.7 | D19: 474.96 | E19: 98.75 | G19: =(C19-C18)/C18 -> 0.052504728 | H19: =(D19-D18)/D18 -> 0.04258495 | I19: =(E19-E18)/E18 -> 0.00094976195 | K19: =G19-I19 -> 0.051554966 | L19: =H19-I19 -> 0.041635188
B20: 44562 | C20: 505.13 | D20: 449.91 | E20: 96.2969 | G20: =(C20-C19)/C19 -> -0.11021666 | H20: =(D20-D19)/D19 -> -0.052741283 | I20: =(E20-E19)/E19 -> -0.024841519 | K20: =G20-I20 -> -0.085375145 | L20: =H20-I20 -> -0.027899764
B21: 44593 | C21: 519.25 | D21: 436.63 | E21: 99.75 | G21: =(C21-C20)/C20 -> 0.0279532 | H21: =(D21-D20)/D20 -> -0.029517015 | I21: =(E21-E20)/E20 -> 0.035858891 | K21: =G21-I21 -> -0.0079056904 | L21: =H21-I21 -> -0.065375905
B22: 44621 | C22: 575.85 | D22: 451.64 | E22: 95.8125 | G22: =(C22-C21)/C21 -> 0.10900337 | H22: =(D22-D21)/D21 -> 0.034376932 | I22: =(E22-E21)/E21 -> -0.039473684 | K22: =G22-I22 -> 0.14847705 | L22: =H22-I22 -> 0.073850617
... B70: 46082 | C70: 1008.43 | D70: 662.29 | E70: 98.7344 | G70: =(C70-C69)/C69 -> -0.0023348074 | H70: =(D70-D69)/D69 -> -0.034548609 | I70: =(E70-E69)/E69 -> -0.026647936 | K70: =G70-I70 -> 0.024313128 | L70: =H70-I70 -> -0.0079006727

Sheet MSFT Equity Beta
B2: #VALUE! | G2: Beta | H2: =INDEX(LINEST(K11:K70,L11:L70,1,1),1,1) -> 1.0757582
B3: #VALUE! | G3: SE Beta | H3: =INDEX(LINEST(K11:K70,L11:L70,1,1),2,1) -> 0.13447305
B4: #VALUE!
B6: 44256
B7: 46082
C9: Price TEGNA | D9: Price S&P 500 | E9: Price US10Y
B10: {=_xlfn.STOCKHISTORY(B2,$B$6,$B$7,2,0)} -> 44256 | C10: 235.77 | D10: {=_xlfn.STOCKHISTORY(B3,$B$6,$B$7,2,0,1)} -> 396.33 | E10: {=_xlfn.STOCKHISTORY(B4,$B$6,$B$7,2,0,1)} -> 94.4844 | G10: ri | H10: rm | I10: rf | K10: ri-rf | L10: rm-rf
B11: 44287 | C11: 252.18 | D11: 417.3 | E11: 95.4844 | G11: =(C11-C10)/C10 -> 0.069601731 | H11: =(D11-D10)/D10 -> 0.052910453 | I11: =(E11-E10)/E10 -> 0.010583758 | K11: =G11-I11 -> 0.059017973 | L11: =H11-I11 -> 0.042326696
B12: 44317 | C12: 249.68 | D12: 420.04 | E12: 100.1406 | G12: =(C12-C11)/C11 -> -0.0099135538 | H12: =(D12-D11)/D11 -> 0.0065660197 | I12: =(E12-E11)/E11 -> 0.048763987 | K12: =G12-I12 -> -0.05867754 | L12: =H12-I12 -> -0.042197967
B13: 44348 | C13: 270.9 | D13: 428.06 | E13: 101.4063 | G13: =(C13-C12)/C12 -> 0.084988786 | H13: =(D13-D12)/D12 -> 0.01909342 | I13: =(E13-E12)/E12 -> 0.012639229 | K13: =G13-I13 -> 0.072349556 | L13: =H13-I13 -> 0.0064541904
B14: 44378 | C14: 284.91 | D14: 438.51 | E14: 103.6719 | G14: =(C14-C13)/C13 -> 0.051716501 | H14: =(D14-D13)/D13 -> 0.024412466 | I14: =(E14-E13)/E13 -> 0.022341807 | K14: =G14-I14 -> 0.029374693 | L14: =H14-I14 -> 0.0020706584
B15: 44409 | C15: 301.88 | D15: 451.56 | E15: 99.4063 | G15: =(C15-C14)/C14 -> 0.059562669 | H15: =(D15-D14)/D14 -> 0.029759869 | I15: =(E15-E14)/E14 -> -0.04114519 | K15: =G15-I15 -> 0.10070786 | L15: =H15-I15 -> 0.070905058
B16: 44440 | C16: 281.92 | D16: 429.14 | E16: 97.7031 | G16: =(C16-C15)/C15 -> -0.066118988 | H16: =(D16-D15)/D15 -> -0.049650102 | I16: =(E16-E15)/E15 -> -0.017133723 | K16: =G16-I16 -> -0.048985265 | L16: =H16-I16 -> -0.032516379
B17: 44470 | C17: 331.62 | D17: 459.25 | E17: 97.0781 | G17: =(C17-C16)/C16 -> 0.17629115 | H17: =(D17-D16)/D16 -> 0.070163583 | I17: =(E17-E16)/E16 -> -0.0063969311 | K17: =G17-I17 -> 0.18268808 | L17: =H17-I17 -> 0.076560514
B18: 44501 | C18: 330.59 | D18: 455.56 | E18: 98.6563 | G18: =(C18-C17)/C17 -> -0.0031059647 | H18: =(D18-D17)/D17 -> -0.0080348394 | I18: =(E18-E17)/E17 -> 0.016257014 | K18: =G18-I18 -> -0.019362978 | L18: =H18-I18 -> -0.024291853
B19: 44531 | C19: 336.32 | D19: 474.96 | E19: 98.75 | G19: =(C19-C18)/C18 -> 0.017332648 | H19: =(D19-D18)/D18 -> 0.04258495 | I19: =(E19-E18)/E18 -> 0.00094976195 | K19: =G19-I19 -> 0.016382886 | L19: =H19-I19 -> 0.041635188
B20: 44562 | C20: 310.98 | D20: 449.91 | E20: 96.2969 | G20: =(C20-C19)/C19 -> -0.07534491 | H20: =(D20-D19)/D19 -> -0.052741283 | I20: =(E20-E19)/E19 -> -0.024841519 | K20: =G20-I20 -> -0.050503391 | L20: =H20-I20 -> -0.027899764
B21: 44593 | C21: 298.79 | D21: 436.63 | E21: 99.75 | G21: =(C21-C20)/C20 -> -0.039198662 | H21: =(D21-D20)/D20 -> -0.029517015 | I21: =(E21-E20)/E20 -> 0.035858891 | K21: =G21-I21 -> -0.075057553 | L21: =H21-I21 -> -0.065375905
B22: 44621 | C22: 308.31 | D22: 451.64 | E22: 95.8125 | G22: =(C22-C21)/C21 -> 0.031861843 | H22: =(D22-D21)/D21 -> 0.034376932 | I22: =(E22-E21)/E21 -> -0.039473684 | K22: =G22-I22 -> 0.071335527 | L22: =H22-I22 -> 0.073850617
... B70: 46082 | C70: 395.55 | D70: 662.29 | E70: 98.7344 | G70: =(C70-C69)/C69 -> 0.0071548607 | H70: =(D70-D69)/D69 -> -0.034548609 | I70: =(E70-E69)/E69 -> -0.026647936 | K70: =G70-I70 -> 0.033802797 | L70: =H70-I70 -> -0.0079006727

Sheet ORCL Equity Beta
B2: #VALUE! | G2: Beta | H2: =INDEX(LINEST(K11:K70,L11:L70,1,1),1,1) -> 1.4690356
B3: #VALUE! | G3: SE Beta | H3: =INDEX(LINEST(K11:K70,L11:L70,1,1),2,1) -> 0.25078233
B4: #VALUE!
B6: 44256
B7: 46082
C9: Price TEGNA | D9: Price S&P 500 | E9: Price US10Y
B10: {=_xlfn.STOCKHISTORY(B2,$B$6,$B$7,2,0)} -> 44256 | C10: 70.17 | D10: {=_xlfn.STOCKHISTORY(B3,$B$6,$B$7,2,0,1)} -> 396.33 | E10: {=_xlfn.STOCKHISTORY(B4,$B$6,$B$7,2,0,1)} -> 94.4844 | G10: ri | H10: rm | I10: rf | K10: ri-rf | L10: rm-rf
B11: 44287 | C11: 75.79 | D11: 417.3 | E11: 95.4844 | G11: =(C11-C10)/C10 -> 0.080091207 | H11: =(D11-D10)/D10 -> 0.052910453 | I11: =(E11-E10)/E10 -> 0.010583758 | K11: =G11-I11 -> 0.069507449 | L11: =H11-I11 -> 0.042326696
B12: 44317 | C12: 78.74 | D12: 420.04 | E12: 100.1406 | G12: =(C12-C11)/C11 -> 0.038923341 | H12: =(D12-D11)/D11 -> 0.0065660197 | I12: =(E12-E11)/E11 -> 0.048763987 | K12: =G12-I12 -> -0.0098406458 | L12: =H12-I12 -> -0.042197967
B13: 44348 | C13: 77.84 | D13: 428.06 | E13: 101.4063 | G13: =(C13-C12)/C12 -> -0.011430023 | H13: =(D13-D12)/D12 -> 0.01909342 | I13: =(E13-E12)/E12 -> 0.012639229 | K13: =G13-I13 -> -0.024069252 | L13: =H13-I13 -> 0.0064541904
B14: 44378 | C14: 87.14 | D14: 438.51 | E14: 103.6719 | G14: =(C14-C13)/C13 -> 0.11947585 | H14: =(D14-D13)/D13 -> 0.024412466 | I14: =(E14-E13)/E13 -> 0.022341807 | K14: =G14-I14 -> 0.097134041 | L14: =H14-I14 -> 0.0020706584
B15: 44409 | C15: 89.13 | D15: 451.56 | E15: 99.4063 | G15: =(C15-C14)/C14 -> 0.022836814 | H15: =(D15-D14)/D14 -> 0.029759869 | I15: =(E15-E14)/E14 -> -0.04114519 | K15: =G15-I15 -> 0.063982004 | L15: =H15-I15 -> 0.070905058
B16: 44440 | C16: 87.13 | D16: 429.14 | E16: 97.7031 | G16: =(C16-C15)/C15 -> -0.022439134 | H16: =(D16-D15)/D15 -> -0.049650102 | I16: =(E16-E15)/E15 -> -0.017133723 | K16: =G16-I16 -> -0.0053054109 | L16: =H16-I16 -> -0.032516379
B17: 44470 | C17: 95.94 | D17: 459.25 | E17: 97.0781 | G17: =(C17-C16)/C16 -> 0.10111328 | H17: =(D17-D16)/D16 -> 0.070163583 | I17: =(E17-E16)/E16 -> -0.0063969311 | K17: =G17-I17 -> 0.10751021 | L17: =H17-I17 -> 0.076560514
B18: 44501 | C18: 90.74 | D18: 455.56 | E18: 98.6563 | G18: =(C18-C17)/C17 -> -0.054200542 | H18: =(D18-D17)/D17 -> -0.0080348394 | I18: =(E18-E17)/E17 -> 0.016257014 | K18: =G18-I18 -> -0.070457556 | L18: =H18-I18 -> -0.024291853
B19: 44531 | C19: 87.21 | D19: 474.96 | E19: 98.75 | G19: =(C19-C18)/C18 -> -0.038902358 | H19: =(D19-D18)/D18 -> 0.04258495 | I19: =(E19-E18)/E18 -> 0.00094976195 | K19: =G19-I19 -> -0.03985212 | L19: =H19-I19 -> 0.041635188
B20: 44562 | C20: 81.16 | D20: 449.91 | E20: 96.2969 | G20: =(C20-C19)/C19 -> -0.069372778 | H20: =(D20-D19)/D19 -> -0.052741283 | I20: =(E20-E19)/E19 -> -0.024841519 | K20: =G20-I20 -> -0.044531259 | L20: =H20-I20 -> -0.027899764
B21: 44593 | C21: 75.97 | D21: 436.63 | E21: 99.75 | G21: =(C21-C20)/C20 -> -0.063947758 | H21: =(D21-D20)/D20 -> -0.029517015 | I21: =(E21-E20)/E20 -> 0.035858891 | K21: =G21-I21 -> -0.099806648 | L21: =H21-I21 -> -0.065375905
B22: 44621 | C22: 82.73 | D22: 451.64 | E22: 95.8125 | G22: =(C22-C21)/C21 -> 0.088982493 | H22: =(D22-D21)/D21 -> 0.034376932 | I22: =(E22-E21)/E21 -> -0.039473684 | K22: =G22-I22 -> 0.12845618 | L22: =H22-I22 -> 0.073850617
... B70: 46082 | C70: 155.11 | D70: 662.29 | E70: 98.7344 | G70: =(C70-C69)/C69 -> 0.066781293 | H70: =(D70-D69)/D69 -> -0.034548609 | I70: =(E70-E69)/E69 -> -0.026647936 | K70: =G70-I70 -> 0.093429229 | L70: =H70-I70 -> -0.0079006727

Sheet WMT Equity Beta
B2: #VALUE! | G2: Beta | H2: =INDEX(LINEST(K11:K70,L11:L70,1,1),1,1) -> 1.0645001
B3: #VALUE! | G3: SE Beta | H3: =INDEX(LINEST(K11:K70,L11:L70,1,1),2,1) -> 0.14129261
B4: #VALUE!
B6: 44256
B7: 46082
C9: Price TEGNA | D9: Price S&P 500 | E9: Price US10Y
B10: {=_xlfn.STOCKHISTORY(B2,$B$6,$B$7,2,0)} -> 44256 | C10: 45.2762 | D10: {=_xlfn.STOCKHISTORY(B3,$B$6,$B$7,2,0,1)} -> 396.33 | E10: {=_xlfn.STOCKHISTORY(B4,$B$6,$B$7,2,0,1)} -> 94.4844 | G10: ri | H10: rm | I10: rf | K10: ri-rf | L10: rm-rf
B11: 44287 | C11: 46.6362 | D11: 417.3 | E11: 95.4844 | G11: =(C11-C10)/C10 -> 0.030037857 | H11: =(D11-D10)/D10 -> 0.052910453 | I11: =(E11-E10)/E10 -> 0.010583758 | K11: =G11-I11 -> 0.019454099 | L11: =H11-I11 -> 0.042326696
B12: 44317 | C12: 47.3429 | D12: 420.04 | E12: 100.1406 | G12: =(C12-C11)/C11 -> 0.015153464 | H12: =(D12-D11)/D11 -> 0.0065660197 | I12: =(E12-E11)/E11 -> 0.048763987 | K12: =G12-I12 -> -0.033610522 | L12: =H12-I12 -> -0.042197967
B13: 44348 | C13: 47.0062 | D13: 428.06 | E13: 101.4063 | G13: =(C13-C12)/C12 -> -0.0071119429 | H13: =(D13-D12)/D12 -> 0.01909342 | I13: =(E13-E12)/E12 -> 0.012639229 | K13: =G13-I13 -> -0.019751172 | L13: =H13-I13 -> 0.0064541904
B14: 44378 | C14: 47.5162 | D14: 438.51 | E14: 103.6719 | G14: =(C14-C13)/C13 -> 0.010849633 | H14: =(D14-D13)/D13 -> 0.024412466 | I14: =(E14-E13)/E13 -> 0.022341807 | K14: =G14-I14 -> -0.011492175 | L14: =H14-I14 -> 0.0020706584
B15: 44409 | C15: 49.3662 | D15: 451.56 | E15: 99.4063 | G15: =(C15-C14)/C14 -> 0.03893409 | H15: =(D15-D14)/D14 -> 0.029759869 | I15: =(E15-E14)/E14 -> -0.04114519 | K15: =G15-I15 -> 0.08007928 | L15: =H15-I15 -> 0.070905058
B16: 44440 | C16: 46.4595 | D16: 429.14 | E16: 97.7031 | G16: =(C16-C15)/C15 -> -0.058880368 | H16: =(D16-D15)/D15 -> -0.049650102 | I16: =(E16-E15)/E15 -> -0.017133723 | K16: =G16-I16 -> -0.041746645 | L16: =H16-I16 -> -0.032516379
B17: 44470 | C17: 49.8062 | D17: 459.25 | E17: 97.0781 | G17: =(C17-C16)/C16 -> 0.072034783 | H17: =(D17-D16)/D16 -> 0.070163583 | I17: =(E17-E16)/E16 -> -0.0063969311 | K17: =G17-I17 -> 0.078431714 | L17: =H17-I17 -> 0.076560514
B18: 44501 | C18: 46.8762 | D18: 455.56 | E18: 98.6563 | G18: =(C18-C17)/C17 -> -0.058828017 | H18: =(D18-D17)/D17 -> -0.0080348394 | I18: =(E18-E17)/E17 -> 0.016257014 | K18: =G18-I18 -> -0.075085031 | L18: =H18-I18 -> -0.024291853
B19: 44531 | C19: 48.2295 | D19: 474.96 | E19: 98.75 | G19: =(C19-C18)/C18 -> 0.028869661 | H19: =(D19-D18)/D18 -> 0.04258495 | I19: =(E19-E18)/E18 -> 0.00094976195 | K19: =G19-I19 -> 0.027919899 | L19: =H19-I19 -> 0.041635188
B20: 44562 | C20: 46.6029 | D20: 449.91 | E20: 96.2969 | G20: =(C20-C19)/C19 -> -0.033726246 | H20: =(D20-D19)/D19 -> -0.052741283 | I20: =(E20-E19)/E19 -> -0.024841519 | K20: =G20-I20 -> -0.0088847274 | L20: =H20-I20 -> -0.027899764
B21: 44593 | C21: 45.0529 | D21: 436.63 | E21: 99.75 | G21: =(C21-C20)/C20 -> -0.033259733 | H21: =(D21-D20)/D20 -> -0.029517015 | I21: =(E21-E20)/E20 -> 0.035858891 | K21: =G21-I21 -> -0.069118623 | L21: =H21-I21 -> -0.065375905
B22: 44621 | C22: 49.6395 | D22: 451.64 | E22: 95.8125 | G22: =(C22-C21)/C21 -> 0.10180477 | H22: =(D22-D21)/D21 -> 0.034376932 | I22: =(E22-E21)/E21 -> -0.039473684 | K22: =G22-I22 -> 0.14127845 | L22: =H22-I22 -> 0.073850617
... B70: 46082 | C70: 126.52 | D70: 662.29 | E70: 98.7344 | G70: =(C70-C69)/C69 -> -0.011176241 | H70: =(D70-D69)/D69 -> -0.034548609 | I70: =(E70-E69)/E69 -> -0.026647936 | K70: =G70-I70 -> 0.015471695 | L70: =H70-I70 -> -0.0079006727

Sheet MELI Equity Beta
B2: #VALUE! | G2: Beta | H2: =INDEX(LINEST(K11:K70,L11:L70,1,1),1,1) -> 1.3673681
B3: #VALUE! | G3: SE Beta | H3: =INDEX(LINEST(K11:K70,L11:L70,1,1),2,1) -> 0.3045188
B4: #VALUE!
B6: 44256
B7: 46082
C9: Price TEGNA | D9: Price S&P 500 | E9: Price US10Y
B10: {=_xlfn.STOCKHISTORY(B2,$B$6,$B$7,2,0)} -> 44256 | C10: 1472.14 | D10: {=_xlfn.STOCKHISTORY(B3,$B$6,$B$7,2,0,1)} -> 396.33 | E10: {=_xlfn.STOCKHISTORY(B4,$B$6,$B$7,2,0,1)} -> 94.4844 | G10: ri | H10: rm | I10: rf | K10: ri-rf | L10: rm-rf
B11: 44287 | C11: 1570.98 | D11: 417.3 | E11: 95.4844 | G11: =(C11-C10)/C10 -> 0.067140353 | H11: =(D11-D10)/D10 -> 0.052910453 | I11: =(E11-E10)/E10 -> 0.010583758 | K11: =G11-I11 -> 0.056556596 | L11: =H11-I11 -> 0.042326696
B12: 44317 | C12: 1358.67 | D12: 420.04 | E12: 100.1406 | G12: =(C12-C11)/C11 -> -0.13514494 | H12: =(D12-D11)/D11 -> 0.0065660197 | I12: =(E12-E11)/E11 -> 0.048763987 | K12: =G12-I12 -> -0.18390893 | L12: =H12-I12 -> -0.042197967
B13: 44348 | C13: 1557.79 | D13: 428.06 | E13: 101.4063 | G13: =(C13-C12)/C12 -> 0.14655509 | H13: =(D13-D12)/D12 -> 0.01909342 | I13: =(E13-E12)/E12 -> 0.012639229 | K13: =G13-I13 -> 0.13391586 | L13: =H13-I13 -> 0.0064541904
B14: 44378 | C14: 1568.7 | D14: 438.51 | E14: 103.6719 | G14: =(C14-C13)/C13 -> 0.0070035114 | H14: =(D14-D13)/D13 -> 0.024412466 | I14: =(E14-E13)/E13 -> 0.022341807 | K14: =G14-I14 -> -0.015338296 | L14: =H14-I14 -> 0.0020706584
B15: 44409 | C15: 1867.45 | D15: 451.56 | E15: 99.4063 | G15: =(C15-C14)/C14 -> 0.19044432 | H15: =(D15-D14)/D14 -> 0.029759869 | I15: =(E15-E14)/E14 -> -0.04114519 | K15: =G15-I15 -> 0.23158951 | L15: =H15-I15 -> 0.070905058
B16: 44440 | C16: 1679.4 | D16: 429.14 | E16: 97.7031 | G16: =(C16-C15)/C15 -> -0.10069881 | H16: =(D16-D15)/D15 -> -0.049650102 | I16: =(E16-E15)/E15 -> -0.017133723 | K16: =G16-I16 -> -0.083565091 | L16: =H16-I16 -> -0.032516379
B17: 44470 | C17: 1481.02 | D17: 459.25 | E17: 97.0781 | G17: =(C17-C16)/C16 -> -0.11812552 | H17: =(D17-D16)/D16 -> 0.070163583 | I17: =(E17-E16)/E16 -> -0.0063969311 | K17: =G17-I17 -> -0.11172859 | L17: =H17-I17 -> 0.076560514
B18: 44501 | C18: 1188.41 | D18: 455.56 | E18: 98.6563 | G18: =(C18-C17)/C17 -> -0.19757329 | H18: =(D18-D17)/D17 -> -0.0080348394 | I18: =(E18-E17)/E17 -> 0.016257014 | K18: =G18-I18 -> -0.21383031 | L18: =H18-I18 -> -0.024291853
B19: 44531 | C19: 1348.4 | D19: 474.96 | E19: 98.75 | G19: =(C19-C18)/C18 -> 0.13462526 | H19: =(D19-D18)/D18 -> 0.04258495 | I19: =(E19-E18)/E18 -> 0.00094976195 | K19: =G19-I19 -> 0.13367549 | L19: =H19-I19 -> 0.041635188
B20: 44562 | C20: 1132.06 | D20: 449.91 | E20: 96.2969 | G20: =(C20-C19)/C19 -> -0.16044201 | H20: =(D20-D19)/D19 -> -0.052741283 | I20: =(E20-E19)/E19 -> -0.024841519 | K20: =G20-I20 -> -0.13560049 | L20: =H20-I20 -> -0.027899764
B21: 44593 | C21: 1126.65 | D21: 436.63 | E21: 99.75 | G21: =(C21-C20)/C20 -> -0.0047788986 | H21: =(D21-D20)/D20 -> -0.029517015 | I21: =(E21-E20)/E20 -> 0.035858891 | K21: =G21-I21 -> -0.040637789 | L21: =H21-I21 -> -0.065375905
B22: 44621 | C22: 1189.48 | D22: 451.64 | E22: 95.8125 | G22: =(C22-C21)/C21 -> 0.055767097 | H22: =(D22-D21)/D21 -> 0.034376932 | I22: =(E22-E21)/E21 -> -0.039473684 | K22: =G22-I22 -> 0.095240781 | L22: =H22-I22 -> 0.073850617
... B70: 46082 | C70: 1670 | D70: 662.29 | E70: 98.7344 | G70: =(C70-C69)/C69 -> -0.04982988 | H70: =(D70-D69)/D69 -> -0.034548609 | I70: =(E70-E69)/E69 -> -0.026647936 | K70: =G70-I70 -> -0.023181944 | L70: =H70-I70 -> -0.0079006727

Sheet BABA Equity Beta
B2: #VALUE! | G2: Beta | H2: =INDEX(LINEST(K11:K70,L11:L70,1,1),1,1) -> 0.085771244
B3: #VALUE! | G3: SE Beta | H3: =INDEX(LINEST(K11:K70,L11:L70,1,1),2,1) -> 0.37903754
B4: #VALUE!
B6: 44256
B7: 46082
C9: Price TEGNA | D9: Price S&P 500 | E9: Price US10Y
B10: {=_xlfn.STOCKHISTORY(B2,$B$6,$B$7,2,0)} -> 44256 | C10: 224.9411 | D10: {=_xlfn.STOCKHISTORY(B3,$B$6,$B$7,2,0,1)} -> 396.33 | E10: {=_xlfn.STOCKHISTORY(B4,$B$6,$B$7,2,0,1)} -> 94.4844 | G10: ri | H10: rm | I10: rf | K10: ri-rf | L10: rm-rf
B11: 44287 | C11: 229.1278 | D11: 417.3 | E11: 95.4844 | G11: =(C11-C10)/C10 -> 0.018612428 | H11: =(D11-D10)/D10 -> 0.052910453 | I11: =(E11-E10)/E10 -> 0.010583758 | K11: =G11-I11 -> 0.0080286701 | L11: =H11-I11 -> 0.042326696
B12: 44317 | C12: 212.2719 | D12: 420.04 | E12: 100.1406 | G12: =(C12-C11)/C11 -> -0.073565495 | H12: =(D12-D11)/D11 -> 0.0065660197 | I12: =(E12-E11)/E11 -> 0.048763987 | K12: =G12-I12 -> -0.12232948 | L12: =H12-I12 -> -0.042197967
B13: 44348 | C13: 224.9907 | D13: 428.06 | E13: 101.4063 | G13: =(C13-C12)/C12 -> 0.059917493 | H13: =(D13-D12)/D12 -> 0.01909342 | I13: =(E13-E12)/E12 -> 0.012639229 | K13: =G13-I13 -> 0.047278263 | L13: =H13-I13 -> 0.0064541904
B14: 44378 | C14: 193.65 | D14: 438.51 | E14: 103.6719 | G14: =(C14-C13)/C13 -> -0.13929776 | H14: =(D14-D13)/D13 -> 0.024412466 | I14: =(E14-E13)/E13 -> 0.022341807 | K14: =G14-I14 -> -0.16163956 | L14: =H14-I14 -> 0.0020706584
B15: 44409 | C15: 165.6724 | D15: 451.56 | E15: 99.4063 | G15: =(C15-C14)/C14 -> -0.14447508 | H15: =(D15-D14)/D14 -> 0.029759869 | I15: =(E15-E14)/E14 -> -0.04114519 | K15: =G15-I15 -> -0.10332989 | L15: =H15-I15 -> 0.070905058
B16: 44440 | C16: 146.8819 | D16: 429.14 | E16: 97.7031 | G16: =(C16-C15)/C15 -> -0.11341962 | H16: =(D16-D15)/D15 -> -0.049650102 | I16: =(E16-E15)/E15 -> -0.017133723 | K16: =G16-I16 -> -0.096285893 | L16: =H16-I16 -> -0.032516379
B17: 44470 | C17: 163.6386 | D17: 459.25 | E17: 97.0781 | G17: =(C17-C16)/C16 -> 0.11408281 | H17: =(D17-D16)/D16 -> 0.070163583 | I17: =(E17-E16)/E16 -> -0.0063969311 | K17: =G17-I17 -> 0.12047974 | L17: =H17-I17 -> 0.076560514
B18: 44501 | C18: 126.5238 | D18: 455.56 | E18: 98.6563 | G18: =(C18-C17)/C17 -> -0.22680957 | H18: =(D18-D17)/D17 -> -0.0080348394 | I18: =(E18-E17)/E17 -> 0.016257014 | K18: =G18-I18 -> -0.24306658 | L18: =H18-I18 -> -0.024291853
B19: 44531 | C19: 117.8527 | D19: 474.96 | E19: 98.75 | G19: =(C19-C18)/C18 -> -0.068533351 | H19: =(D19-D18)/D18 -> 0.04258495 | I19: =(E19-E18)/E18 -> 0.00094976195 | K19: =G19-I19 -> -0.069483113 | L19: =H19-I19 -> 0.041635188
B20: 44562 | C20: 124.7975 | D20: 449.91 | E20: 96.2969 | G20: =(C20-C19)/C19 -> 0.058927797 | H20: =(D20-D19)/D19 -> -0.052741283 | I20: =(E20-E19)/E19 -> -0.024841519 | K20: =G20-I20 -> 0.083769316 | L20: =H20-I20 -> -0.027899764
B21: 44593 | C21: 104.3601 | D21: 436.63 | E21: 99.75 | G21: =(C21-C20)/C20 -> -0.1637645 | H21: =(D21-D20)/D20 -> -0.029517015 | I21: =(E21-E20)/E20 -> 0.035858891 | K21: =G21-I21 -> -0.19962339 | L21: =H21-I21 -> -0.065375905
B22: 44621 | C22: 107.9416 | D22: 451.64 | E22: 95.8125 | G22: =(C22-C21)/C21 -> 0.034318672 | H22: =(D22-D21)/D21 -> 0.034376932 | I22: =(E22-E21)/E21 -> -0.039473684 | K22: =G22-I22 -> 0.073792356 | L22: =H22-I22 -> 0.073850617
... B70: 46082 | C70: 135.21 | D70: 662.29 | E70: 98.7344 | G70: =(C70-C69)/C69 -> -0.061758379 | H70: =(D70-D69)/D69 -> -0.034548609 | I70: =(E70-E69)/E69 -> -0.026647936 | K70: =G70-I70 -> -0.035110443 | L70: =H70-I70 -> -0.0079006727

Sheet NXST Comp Equity Beta
B2: #VALUE! | G2: Beta | H2: =INDEX(LINEST(K11:K70,L11:L70,1,1),1,1) -> 0.53848843
B3: #VALUE! | G3: SE Beta | H3: =INDEX(LINEST(K11:K70,L11:L70,1,1),2,1) -> 0.20967169
B4: #VALUE!
B6: 44256
B7: 46082
C9: Price TEGNA | D9: Price S&P 500 | E9: Price US10Y
B10: {=_xlfn.STOCKHISTORY(B2,$B$6,$B$7,2,0)} -> 44256 | C10: 140.43 | D10: {=_xlfn.STOCKHISTORY(B3,$B$6,$B$7,2,0,1)} -> 396.33 | E10: {=_xlfn.STOCKHISTORY(B4,$B$6,$B$7,2,0,1)} -> 94.4844 | G10: ri | H10: rm | I10: rf | K10: ri-rf | L10: rm-rf
B11: 44287 | C11: 147.41 | D11: 417.3 | E11: 95.4844 | G11: =(C11-C10)/C10 -> 0.049704479 | H11: =(D11-D10)/D10 -> 0.052910453 | I11: =(E11-E10)/E10 -> 0.010583758 | K11: =G11-I11 -> 0.039120721 | L11: =H11-I11 -> 0.042326696
B12: 44317 | C12: 151.91 | D12: 420.04 | E12: 100.1406 | G12: =(C12-C11)/C11 -> 0.030527101 | H12: =(D12-D11)/D11 -> 0.0065660197 | I12: =(E12-E11)/E11 -> 0.048763987 | K12: =G12-I12 -> -0.018236885 | L12: =H12-I12 -> -0.042197967
B13: 44348 | C13: 147.88 | D13: 428.06 | E13: 101.4063 | G13: =(C13-C12)/C12 -> -0.026528866 | H13: =(D13-D12)/D12 -> 0.01909342 | I13: =(E13-E12)/E12 -> 0.012639229 | K13: =G13-I13 -> -0.039168095 | L13: =H13-I13 -> 0.0064541904
B14: 44378 | C14: 147.07 | D14: 438.51 | E14: 103.6719 | G14: =(C14-C13)/C13 -> -0.0054774141 | H14: =(D14-D13)/D13 -> 0.024412466 | I14: =(E14-E13)/E13 -> 0.022341807 | K14: =G14-I14 -> -0.027819221 | L14: =H14-I14 -> 0.0020706584
B15: 44409 | C15: 149.75 | D15: 451.56 | E15: 99.4063 | G15: =(C15-C14)/C14 -> 0.018222615 | H15: =(D15-D14)/D14 -> 0.029759869 | I15: =(E15-E14)/E14 -> -0.04114519 | K15: =G15-I15 -> 0.059367805 | L15: =H15-I15 -> 0.070905058
B16: 44440 | C16: 151.96 | D16: 429.14 | E16: 97.7031 | G16: =(C16-C15)/C15 -> 0.01475793 | H16: =(D16-D15)/D15 -> -0.049650102 | I16: =(E16-E15)/E15 -> -0.017133723 | K16: =G16-I16 -> 0.031891653 | L16: =H16-I16 -> -0.032516379
B17: 44470 | C17: 149.93 | D17: 459.25 | E17: 97.0781 | G17: =(C17-C16)/C16 -> -0.013358779 | H17: =(D17-D16)/D16 -> 0.070163583 | I17: =(E17-E16)/E16 -> -0.0063969311 | K17: =G17-I17 -> -0.0069618475 | L17: =H17-I17 -> 0.076560514
B18: 44501 | C18: 149.5 | D18: 455.56 | E18: 98.6563 | G18: =(C18-C17)/C17 -> -0.0028680051 | H18: =(D18-D17)/D17 -> -0.0080348394 | I18: =(E18-E17)/E17 -> 0.016257014 | K18: =G18-I18 -> -0.019125019 | L18: =H18-I18 -> -0.024291853
B19: 44531 | C19: 150.98 | D19: 474.96 | E19: 98.75 | G19: =(C19-C18)/C18 -> 0.0098996656 | H19: =(D19-D18)/D18 -> 0.04258495 | I19: =(E19-E18)/E18 -> 0.00094976195 | K19: =G19-I19 -> 0.0089499036 | L19: =H19-I19 -> 0.041635188
B20: 44562 | C20: 165.38 | D20: 449.91 | E20: 96.2969 | G20: =(C20-C19)/C19 -> 0.095376871 | H20: =(D20-D19)/D19 -> -0.052741283 | I20: =(E20-E19)/E19 -> -0.024841519 | K20: =G20-I20 -> 0.12021839 | L20: =H20-I20 -> -0.027899764
B21: 44593 | C21: 185.05 | D21: 436.63 | E21: 99.75 | G21: =(C21-C20)/C20 -> 0.1189382 | H21: =(D21-D20)/D20 -> -0.029517015 | I21: =(E21-E20)/E20 -> 0.035858891 | K21: =G21-I21 -> 0.083079312 | L21: =H21-I21 -> -0.065375905
B22: 44621 | C22: 188.48 | D22: 451.64 | E22: 95.8125 | G22: =(C22-C21)/C21 -> 0.018535531 | H22: =(D22-D21)/D21 -> 0.034376932 | I22: =(E22-E21)/E21 -> -0.039473684 | K22: =G22-I22 -> 0.058009215 | L22: =H22-I22 -> 0.073850617
... B70: 46082 | C70: 233.61 | D70: 662.29 | E70: 98.7344 | G70: =(C70-C69)/C69 -> -0.069357023 | H70: =(D70-D69)/D69 -> -0.034548609 | I70: =(E70-E69)/E69 -> -0.026647936 | K70: =G70-I70 -> -0.042709087 | L70: =H70-I70 -> -0.0079006727

Sheet GTN Comp Equity Beta
B2: #VALUE! | G2: Beta | H2: =INDEX(LINEST(K11:K70,L11:L70,1,1),1,1) -> 0.5796902
B3: #VALUE! | G3: SE Beta | H3: =INDEX(LINEST(K11:K70,L11:L70,1,1),2,1) -> 0.40154849
B4: #VALUE!
B6: 44256
B7: 46082
C9: Price TEGNA | D9: Price S&P 500 | E9: Price US10Y
B10: {=_xlfn.STOCKHISTORY(B2,$B$6,$B$7,2,0)} -> 44256 | C10: 18.4 | D10: {=_xlfn.STOCKHISTORY(B3,$B$6,$B$7,2,0,1)} -> 396.33 | E10: {=_xlfn.STOCKHISTORY(B4,$B$6,$B$7,2,0,1)} -> 94.4844 | G10: ri | H10: rm | I10: rf | K10: ri-rf | L10: rm-rf
B11: 44287 | C11: 20.32 | D11: 417.3 | E11: 95.4844 | G11: =(C11-C10)/C10 -> 0.10434783 | H11: =(D11-D10)/D10 -> 0.052910453 | I11: =(E11-E10)/E10 -> 0.010583758 | K11: =G11-I11 -> 0.093764068 | L11: =H11-I11 -> 0.042326696
B12: 44317 | C12: 23.26 | D12: 420.04 | E12: 100.1406 | G12: =(C12-C11)/C11 -> 0.14468504 | H12: =(D12-D11)/D11 -> 0.0065660197 | I12: =(E12-E11)/E11 -> 0.048763987 | K12: =G12-I12 -> 0.095921053 | L12: =H12-I12 -> -0.042197967
B13: 44348 | C13: 23.4 | D13: 428.06 | E13: 101.4063 | G13: =(C13-C12)/C12 -> 0.0060189166 | H13: =(D13-D12)/D12 -> 0.01909342 | I13: =(E13-E12)/E12 -> 0.012639229 | K13: =G13-I13 -> -0.0066203126 | L13: =H13-I13 -> 0.0064541904
B14: 44378 | C14: 22.17 | D14: 438.51 | E14: 103.6719 | G14: =(C14-C13)/C13 -> -0.052564103 | H14: =(D14-D13)/D13 -> 0.024412466 | I14: =(E14-E13)/E13 -> 0.022341807 | K14: =G14-I14 -> -0.07490591 | L14: =H14-I14 -> 0.0020706584
B15: 44409 | C15: 22.74 | D15: 451.56 | E15: 99.4063 | G15: =(C15-C14)/C14 -> 0.025710419 | H15: =(D15-D14)/D14 -> 0.029759869 | I15: =(E15-E14)/E14 -> -0.04114519 | K15: =G15-I15 -> 0.066855609 | L15: =H15-I15 -> 0.070905058
B16: 44440 | C16: 22.82 | D16: 429.14 | E16: 97.7031 | G16: =(C16-C15)/C15 -> 0.0035180299 | H16: =(D16-D15)/D15 -> -0.049650102 | I16: =(E16-E15)/E15 -> -0.017133723 | K16: =G16-I16 -> 0.020651753 | L16: =H16-I16 -> -0.032516379
B17: 44470 | C17: 23.44 | D17: 459.25 | E17: 97.0781 | G17: =(C17-C16)/C16 -> 0.02716915 | H17: =(D17-D16)/D16 -> 0.070163583 | I17: =(E17-E16)/E16 -> -0.0063969311 | K17: =G17-I17 -> 0.033566081 | L17: =H17-I17 -> 0.076560514
B18: 44501 | C18: 20.62 | D18: 455.56 | E18: 98.6563 | G18: =(C18-C17)/C17 -> -0.12030717 | H18: =(D18-D17)/D17 -> -0.0080348394 | I18: =(E18-E17)/E17 -> 0.016257014 | K18: =G18-I18 -> -0.13656418 | L18: =H18-I18 -> -0.024291853
B19: 44531 | C19: 20.16 | D19: 474.96 | E19: 98.75 | G19: =(C19-C18)/C18 -> -0.022308438 | H19: =(D19-D18)/D18 -> 0.04258495 | I19: =(E19-E18)/E18 -> 0.00094976195 | K19: =G19-I19 -> -0.0232582 | L19: =H19-I19 -> 0.041635188
B20: 44562 | C20: 20.85 | D20: 449.91 | E20: 96.2969 | G20: =(C20-C19)/C19 -> 0.03422619 | H20: =(D20-D19)/D19 -> -0.052741283 | I20: =(E20-E19)/E19 -> -0.024841519 | K20: =G20-I20 -> 0.059067709 | L20: =H20-I20 -> -0.027899764
B21: 44593 | C21: 23.43 | D21: 436.63 | E21: 99.75 | G21: =(C21-C20)/C20 -> 0.12374101 | H21: =(D21-D20)/D20 -> -0.029517015 | I21: =(E21-E20)/E20 -> 0.035858891 | K21: =G21-I21 -> 0.087882117 | L21: =H21-I21 -> -0.065375905
B22: 44621 | C22: 22.07 | D22: 451.64 | E22: 95.8125 | G22: =(C22-C21)/C21 -> -0.058045241 | H22: =(D22-D21)/D21 -> 0.034376932 | I22: =(E22-E21)/E21 -> -0.039473684 | K22: =G22-I22 -> -0.018571557 | L22: =H22-I22 -> 0.073850617
... B70: 46082 | C70: 4.63 | D70: 662.29 | E70: 98.7344 | G70: =(C70-C69)/C69 -> -0.10789981 | H70: =(D70-D69)/D69 -> -0.034548609 | I70: =(E70-E69)/E69 -> -0.026647936 | K70: =G70-I70 -> -0.081251871 | L70: =H70-I70 -> -0.0079006727

Sheet SGBI Comp Equity Beta
B2: #VALUE! | G2: Beta | H2: =INDEX(LINEST(K11:K70,L11:L70,1,1),1,1) -> 0.36679148
B3: #VALUE! | G3: SE Beta | H3: =INDEX(LINEST(K11:K70,L11:L70,1,1),2,1) -> 0.29488139
B4: #VALUE!
B6: 44256
B7: 46082
C9: Price TEGNA | D9: Price S&P 500 | E9: Price US10Y
